{"uuid": "d2640fc3-519a-44e1-b400-c747a7dd206f", "children": ["50fbf996-b183-42bb-a127-b3c6a890fc21"], "befores": [{"name": "fixtures_ver", "status": "broken", "statusDetails": {"message": "_pytest.outcomes.Exit: unable to communicate to ControllerHTTPSConnectionPool(host='sec-ucentral-qa01.cicd.lab.wlan.tip.build', port=16001): Max retries exceeded with url: /api/v1/oauth2 (Caused by NewConnectionError('<urllib3.connection.HTTPSConnection object at 0x7fde87305a00>: Failed to establish a new connection: [Errno -3] Temporary failure in name resolution'))\n", "trace": "  File \"/usr/local/lib/python3.8/site-packages/pluggy/callers.py\", line 187, in _multicall\n    res = hook_impl.function(*args)\n  File \"/usr/local/lib/python3.8/site-packages/_pytest/fixtures.py\", line 1126, in pytest_fixture_setup\n    result = call_fixture_func(fixturefunc, request, kwargs)\n  File \"/usr/local/lib/python3.8/site-packages/_pytest/fixtures.py\", line 925, in call_fixture_func\n    fixture_result = next(generator)\n  File \"/wlan-testing/tests/conftest.py\", line 648, in fixtures_ver\n    obj = Fixtures_2x(configuration=get_configuration)\n  File \"/wlan-testing/tests/fixtures_2x.py\", line 49, in __init__\n    pytest.exit(\"unable to communicate to Controller\" + str(e))\n  File \"/usr/local/lib/python3.8/site-packages/_pytest/outcomes.py\", line 115, in exit\n    raise Exit(msg, returncode)\n"}, "attachments": [{"name": "Controller Instantiation Failed: ", "source": "0c1ebed8-f742-4158-b0cb-8e896333cf9a-attachment.attach"}], "start": 1628641490391, "stop": 1628641510442}], "start": 1628641490391, "stop": 1628641511581}