{"uuid": "ffeb82e8-2741-454d-9760-8efda3297922", "children": ["91050492-887b-40c3-a705-ae524c9f6b0f"], "befores": [{"name": "fixtures_ver", "status": "broken", "statusDetails": {"message": "_pytest.outcomes.Exit: unable to communicate to ControllerHTTPSConnectionPool(host='sec-ucentral-qa01.cicd.lab.wlan.tip.build', port=16001): Max retries exceeded with url: /api/v1/oauth2 (Caused by NewConnectionError('<urllib3.connection.HTTPSConnection object at 0x7fb85f90a850>: Failed to establish a new connection: [Errno -3] Temporary failure in name resolution'))\n", "trace": "  File \"/usr/local/lib/python3.8/site-packages/pluggy/callers.py\", line 187, in _multicall\n    res = hook_impl.function(*args)\n  File \"/usr/local/lib/python3.8/site-packages/_pytest/fixtures.py\", line 1126, in pytest_fixture_setup\n    result = call_fixture_func(fixturefunc, request, kwargs)\n  File \"/usr/local/lib/python3.8/site-packages/_pytest/fixtures.py\", line 925, in call_fixture_func\n    fixture_result = next(generator)\n  File \"/wlan-testing/tests/conftest.py\", line 648, in fixtures_ver\n    obj = Fixtures_2x(configuration=get_configuration)\n  File \"/wlan-testing/tests/fixtures_2x.py\", line 49, in __init__\n    pytest.exit(\"unable to communicate to Controller\" + str(e))\n  File \"/usr/local/lib/python3.8/site-packages/_pytest/outcomes.py\", line 115, in exit\n    raise Exit(msg, returncode)\n"}, "attachments": [{"name": "Controller Instantiation Failed: ", "source": "20020138-0cbe-4a07-9fd0-205ac37c4828-attachment.attach"}], "start": 1628641492145, "stop": 1628641512169}], "start": 1628641492145, "stop": 1628641515286}