{"uuid": "123f316e-d290-4023-870b-96ff5d323823", "children": ["d2d721d8-1538-48b0-ab5d-f9fdd4a9b54e"], "befores": [{"name": "fixtures_ver", "status": "broken", "statusDetails": {"message": "_pytest.outcomes.Exit: unable to communicate to ControllerHTTPSConnectionPool(host='sec-ucentral-qa01.cicd.lab.wlan.tip.build', port=16001): Max retries exceeded with url: /api/v1/oauth2 (Caused by NewConnectionError('<urllib3.connection.HTTPSConnection object at 0x7f14647ba3a0>: Failed to establish a new connection: [Errno -3] Temporary failure in name resolution'))\n", "trace": "  File \"/usr/local/lib/python3.8/site-packages/pluggy/callers.py\", line 187, in _multicall\n    res = hook_impl.function(*args)\n  File \"/usr/local/lib/python3.8/site-packages/_pytest/fixtures.py\", line 1126, in pytest_fixture_setup\n    result = call_fixture_func(fixturefunc, request, kwargs)\n  File \"/usr/local/lib/python3.8/site-packages/_pytest/fixtures.py\", line 925, in call_fixture_func\n    fixture_result = next(generator)\n  File \"/wlan-testing/tests/conftest.py\", line 648, in fixtures_ver\n    obj = Fixtures_2x(configuration=get_configuration)\n  File \"/wlan-testing/tests/fixtures_2x.py\", line 49, in __init__\n    pytest.exit(\"unable to communicate to Controller\" + str(e))\n  File \"/usr/local/lib/python3.8/site-packages/_pytest/outcomes.py\", line 115, in exit\n    raise Exit(msg, returncode)\n"}, "attachments": [{"name": "Controller Instantiation Failed: ", "source": "c809aff1-9f07-4deb-beca-ce068e80100b-attachment.attach"}], "start": 1628622826367, "stop": 1628622846389}], "start": 1628622826367, "stop": 1628622847611}